<?xml version="1.0" ?>
<robot name="panda" xmlns:xacro="http://www.ros.org/wiki/xacro">

  <mujoco>
    <compiler meshdir="../meshes" discardvisual="false" />
  </mujoco>
  
  <link name="panda_link0">
    <visual>
      <geometry>
        <mesh filename="file:///home/zhourui/Desktop/user/project/TeleVision/assets/franka_pinocchio/meshes/visual/link0.dae"/>
      </geometry>
    </visual>
    <collision>
      <geometry>
        <mesh filename="file:///home/zhourui/Desktop/user/project/TeleVision/assets/franka_pinocchio/meshes/collision/link0.obj"/>
      </geometry>
    </collision>
  </link>
  <link name="panda_link1">
    <visual>
      <geometry>
        <mesh filename="file:///home/zhourui/Desktop/user/project/TeleVision/assets/franka_pinocchio/meshes/visual/link1.dae"/>
      </geometry>
    </visual>
    <collision>
      <geometry>
        <mesh filename="file:///home/zhourui/Desktop/user/project/TeleVision/assets/franka_pinocchio/meshes/collision/link1.obj"/>
      </geometry>
    </collision>
  </link>
  <joint name="panda_joint1" type="revolute">
    <safety_controller k_position="100.0" k_velocity="40.0" soft_lower_limit="-2.8973" soft_upper_limit="2.8973"/>
    <origin rpy="0 0 0" xyz="0 0 0.333"/>
    <parent link="panda_link0"/>
    <child link="panda_link1"/>
    <axis xyz="0 0 1"/>
    <dynamics damping="10.0"/>
    <limit effort="87" lower="-2.8973" upper="2.8973" velocity="2.1750"/>
  </joint>
  <link name="panda_link2">
    <visual>
      <geometry>
        <mesh filename="file:///home/zhourui/Desktop/user/project/TeleVision/assets/franka_pinocchio/meshes/visual/link2.dae"/>
      </geometry>
    </visual>
    <collision>
      <geometry>
        <mesh filename="file:///home/zhourui/Desktop/user/project/TeleVision/assets/franka_pinocchio/meshes/collision/link2.obj"/>
      </geometry>
    </collision>
  </link>
  <joint name="panda_joint2" type="revolute">
    <safety_controller k_position="100.0" k_velocity="40.0" soft_lower_limit="-1.7628" soft_upper_limit="1.7628"/>
    <origin rpy="-1.57079632679 0 0" xyz="0 0 0"/>
    <parent link="panda_link1"/>
    <child link="panda_link2"/>
    <axis xyz="0 0 1"/>
    <dynamics damping="10.0"/>
    <limit effort="87" lower="-1.7628" upper="1.7628" velocity="2.1750"/>
  </joint>
  <link name="panda_link3">
    <visual>
      <geometry>
        <mesh filename="file:///home/zhourui/Desktop/user/project/TeleVision/assets/franka_pinocchio/meshes/visual/link3.dae"/>
      </geometry>
    </visual>
    <collision>
      <geometry>
        <mesh filename="file:///home/zhourui/Desktop/user/project/TeleVision/assets/franka_pinocchio/meshes/collision/link3.obj"/>
      </geometry>
    </collision>
  </link>
  <joint name="panda_joint3" type="revolute">
    <safety_controller k_position="100.0" k_velocity="40.0" soft_lower_limit="-2.8973" soft_upper_limit="2.8973"/>
    <origin rpy="1.57079632679 0 0" xyz="0 -0.316 0"/>
    <parent link="panda_link2"/>
    <child link="panda_link3"/>
    <axis xyz="0 0 1"/>
    <dynamics damping="10.0"/>
    <limit effort="87" lower="-2.8973" upper="2.8973" velocity="2.1750"/>
  </joint>
  <link name="panda_link4">
    <visual>
      <geometry>
        <mesh filename="file:///home/zhourui/Desktop/user/project/TeleVision/assets/franka_pinocchio/meshes/visual/link4.dae"/>
      </geometry>
    </visual>
    <collision>
      <geometry>
        <mesh filename="file:///home/zhourui/Desktop/user/project/TeleVision/assets/franka_pinocchio/meshes/collision/link4.obj"/>
      </geometry>
    </collision>
  </link>
  <joint name="panda_joint4" type="revolute">
    <safety_controller k_position="100.0" k_velocity="40.0" soft_lower_limit="-3.0718" soft_upper_limit="-0.0698"/>
    <origin rpy="1.57079632679 0 0" xyz="0.0825 0 0"/>
    <parent link="panda_link3"/>
    <child link="panda_link4"/>
    <axis xyz="0 0 1"/>    
    <dynamics damping="10.0"/>
    <limit effort="87" lower="-3.0718" upper="-0.0698" velocity="2.1750"/>
    <!-- something is weird with this joint limit config
    <dynamics damping="10.0"/>
    <limit effort="87" lower="-3.0" upper="0.087" velocity="2.1750"/>  -->
  </joint>
  <link name="panda_link5">
    <visual>
      <geometry>
        <mesh filename="file:///home/zhourui/Desktop/user/project/TeleVision/assets/franka_pinocchio/meshes/visual/link5.dae"/>
      </geometry>
    </visual>
    <collision>
      <geometry>
        <mesh filename="file:///home/zhourui/Desktop/user/project/TeleVision/assets/franka_pinocchio/meshes/collision/link5.obj"/>
      </geometry>
    </collision>
  </link>
  <joint name="panda_joint5" type="revolute">
    <safety_controller k_position="100.0" k_velocity="40.0" soft_lower_limit="-2.8973" soft_upper_limit="2.8973"/>
    <origin rpy="-1.57079632679 0 0" xyz="-0.0825 0.384 0"/>
    <parent link="panda_link4"/>
    <child link="panda_link5"/>
    <axis xyz="0 0 1"/>
    <dynamics damping="10.0"/>
    <limit effort="87" lower="-2.8973" upper="2.8973" velocity="2.1750"/>
  </joint>
  <link name="panda_link6">
    <visual>
      <geometry>
        <mesh filename="file:///home/zhourui/Desktop/user/project/TeleVision/assets/franka_pinocchio/meshes/visual/link6.dae"/>
      </geometry>
    </visual>
    <collision>
      <geometry>
        <mesh filename="file:///home/zhourui/Desktop/user/project/TeleVision/assets/franka_pinocchio/meshes/collision/link6.obj"/>
      </geometry>
    </collision>
  </link>
  <joint name="panda_joint6" type="revolute">
    <safety_controller k_position="100.0" k_velocity="40.0" soft_lower_limit="-0.0175" soft_upper_limit="3.7525"/>
    <origin rpy="1.57079632679 0 0" xyz="0 0 0"/>
    <parent link="panda_link5"/>
    <child link="panda_link6"/>
    <axis xyz="0 0 1"/>
    <dynamics damping="10.0"/>
    <limit effort="87" lower="-0.0175" upper="3.7525" velocity="2.1750"/>
    <!-- <dynamics damping="10.0"/>
    <limit effort="12" lower="-0.0873" upper="3.0" velocity="2.6100"/> -->
  </joint>
  <link name="panda_link7">
    <visual>
      <geometry>
        <mesh filename="file:///home/zhourui/Desktop/user/project/TeleVision/assets/franka_pinocchio/meshes/visual/link7.dae"/>
      </geometry>
    </visual>
    <collision>
      <geometry>
        <mesh filename="file:///home/zhourui/Desktop/user/project/TeleVision/assets/franka_pinocchio/meshes/collision/link7.obj"/>
      </geometry>
    </collision>
  </link>
  <joint name="panda_joint7" type="revolute">
    <safety_controller k_position="100.0" k_velocity="40.0" soft_lower_limit="-2.8973" soft_upper_limit="2.8973"/>
    <origin rpy="1.57079632679 0 0" xyz="0.088 0 0"/>
    <parent link="panda_link6"/>
    <child link="panda_link7"/>
    <axis xyz="0 0 1"/>
    <dynamics damping="10.0"/>
    <limit effort="87" lower="-2.8973" upper="2.8973" velocity="2.1750"/>
  </joint>
  
  <link name="wrist_connnect">
    <visual>
      <geometry>
        <mesh filename="file:///home/zhourui/Desktop/user/project/dex-mimic/assets/franka_pinocchio/meshes/visual/wrist_connect5.STL"/>
      </geometry>
    </visual>
    <collision>
      <geometry>
        <mesh filename="file:///home/zhourui/Desktop/user/project/dex-mimic/assets/franka_pinocchio/meshes/visual/wrist_connect5.STL"/>
      </geometry>
    </collision>
  </link>



  <joint name="arm_wrist_joint" type="fixed">
    <!--
    <parent link="panda_link8"/>
    -->
    <parent link="panda_link7"/>
    <child link="wrist_connnect"/>
    <!-- <origin rpy="-1.5707963 0 -0.785398163397" xyz="0 0 0.107"/> -->
    <origin rpy="-1.5707963 0 -1.5707963267948966" xyz="0 0 0.116"/>
    <!--
    <origin rpy="0 0 -0.785398163397" xyz="0 0 0"/>
    -->
  </joint>

    <joint name="wrist_hand_joint" type="fixed">
    <!--
    <parent link="panda_link8"/>
    -->
    <parent link="wrist_connnect"/>
    <child link="hand_base_link"/>
    <!-- <origin rpy="-1.5707963 0 -0.785398163397" xyz="0 0 0.107"/> -->
    <origin rpy="-1.5707963 0 1.5707963267948966" xyz="0 -0.02696 0.0447"/>
    <!--
    <origin rpy="0 0 -0.785398163397" xyz="0 0 0"/>
    -->
  </joint>

  <link name="hand_base_link">
    <inertial>
      <origin xyz="-0.0025264 -0.066047 0.0019598" rpy="0 0 0"/>
      <mass value="0.14143"/>
      <inertia ixx="0.00012281" ixy="2.1711E-06" ixz="1.7709E-06" iyy="8.3832E-05" iyz="-1.6551E-06" izz="7.6663E-05"/>
    </inertial>
    <visual>
      <origin xyz="0 0 0" rpy="0 0 0"/>
      <geometry>
        <mesh filename="file:///home/zhourui/Desktop/user/project/dex-mimic/assets/franka_pinocchio/robots/meshes/right_base_link.glb"/>
      </geometry>
    </visual>
    <collision>
      <origin xyz="0 -0.0136 0" rpy="1.57079 0 0"/>
      <geometry>
        <cylinder length="0.0278" radius="0.028"/>
      </geometry>
    </collision>
    <collision>
      <origin xyz="-0.0032 -0.038 0" rpy="0 0 0"/>
      <geometry>
        <box size="0.0391 0.0202 0.0574"/>
      </geometry>
    </collision>
    <collision>
      <origin xyz="-0.0032 -0.0682 0" rpy="0 0 0"/>
      <geometry>
        <box size="0.0391 0.04 0.0814"/>
      </geometry>
    </collision>
    <collision>
      <origin xyz="0 -0.1081 0" rpy="0 0 0"/>
      <geometry>
        <box size="0.0322 0.04 0.0814"/>
      </geometry>
    </collision>
    <collision>
      <origin xyz="-0.0016 -0.1340 0.0309" rpy="0 0 0"/>
      <geometry>
        <box size="0.0125 0.0111 0.0089"/>
      </geometry>
    </collision>
    <collision>
      <origin xyz="-0.0016 -0.1340 0.0118" rpy="0 0 0"/>
      <geometry>
        <box size="0.0125 0.0111 0.0089"/>
      </geometry>
    </collision>
    <collision>
      <origin xyz="-0.0016 -0.1340 -0.0070" rpy="0 0 0"/>
      <geometry>
        <box size="0.0125 0.0111 0.0089"/>
      </geometry>
    </collision>
    <collision>
      <origin xyz="-0.0016 -0.1340 -0.0262" rpy="0 0 0"/>
      <geometry>
        <box size="0.0125 0.0111 0.0089"/>
      </geometry>
    </collision>
  </link>

</robot>






